<?xml version='1.0'?>

<robot name="trixy" xmlns:xacro="http://www.ros.org/wiki/xacro">

  <xacro:include filename="$(find trixy)/urdf/trixy.gazebo" />
  
  <gazebo reference="left_wheel">
    <material>Gazebo/Green</material>
  </gazebo>

  <gazebo reference="right_wheel">
    <material>Gazebo/Green</material>
  </gazebo>

  <gazebo reference="camera">
    <material>Gazebo/Red</material>
  </gazebo>

  <gazebo reference="chassis">
    <material>Gazebo/Blue</material>
  </gazebo>
  <link name="robot_footprint"></link>

  <joint name="robot_footprint_joint" type="fixed">
    <origin xyz="0 0 0" rpy="0 0 0" />
    <parent link="robot_footprint"/>
    <child link="chassis" />
  </joint>

  <joint name="camera_joint" type="fixed">
    <origin xyz="0.17 0 0.05" rpy="0 0 0" />
    <parent link="chassis"/>
    <child link="camera" />  
    <axis xyz="0 1 0"/> 
  </joint>

  <joint name="camara_trasera_joint" type="fixed">
    <origin xyz="-0.17 0 0.05" rpy="0 0 3.14" />
    <parent link="chassis"/>
    <child link="camara_trasera" />  
    <axis xyz="0 1 0"/> 
  </joint>

  <joint name="hokuyo_joint" type="fixed">
    <origin xyz="0.10 -0.03 0.15" rpy="0 0 0" />
    <parent link="chassis"/>
    <child link="hokuyo" />  
    <axis xyz="0 1 0"/> 
  </joint>

  <joint type="continuous" name="left_wheel_hinge">
    <origin xyz="0 0.17 0" rpy="0 0 0" />
    <parent link="chassis"/>
    <child link="left_wheel" />
    <axis xyz="0 1 0" rpy="0 0 0" />
    <limit effort="10000" velocity="1000" />
    <dynamics damping="1.0" friction="1.0" />
  </joint>

  <joint type="continuous" name="right_wheel_hinge">
    <origin xyz="0 -0.17 0" rpy="0 0 0" />
    <parent link="chassis"/>
    <child link="right_wheel" />
    <axis xyz="0 1 0" rpy="0 0 0" />
    <limit effort="10000" velocity="1000" />
    <dynamics damping="1.0" friction="1.0" />
  </joint>

  
<link name="camera">
    <inertial>
      <mass value="0.1"/>
      <origin xyz="0 0 0" rpy="0 0 0"/>
      <inertia
        ixx="1e-6" ixy="0.0" ixz="0.0"
        iyy="1e-6" iyz="0.0"
        izz="1e-6"
      />
    </inertial>

    <collision>
      <origin xyz="0 0 0" rpy="0 0 0"/>
      <geometry>
        <box size="0.05 0.05 0.05"/>
      </geometry>
    </collision>

    <visual>
      <origin xyz="0 0 0" rpy="0 0 0"/>
      <geometry>
        <box size="0.05 0.05 0.05"/>
      </geometry>
    </visual>

  </link>

  <link name="camara_trasera">
    <inertial>
      <mass value="0.1"/>
      <origin xyz="0 0 0" rpy="0 0 0"/>
      <inertia
        ixx="1e-6" ixy="0.0" ixz="0.0"
        iyy="1e-6" iyz="0.0"
        izz="1e-6"
      />
    </inertial>

    <collision>
      <origin xyz="0 0 0" rpy="0 0 0"/>
      <geometry>
        <box size="0.05 0.05 0.05"/>
      </geometry>
    </collision>

    <visual>
      <origin xyz="0 0 0" rpy="0 0 0"/>
      <geometry>
        <box size="0.05 0.05 0.05"/>
      </geometry>
    </visual>

  </link>

  <link name="hokuyo">
    <inertial>
      <mass value="1e-5"/>
      <origin xyz="0 0 0" rpy="0 0 0"/>
      <inertia
        ixx="1e-6" ixy="0.0" ixz="0.0"
        iyy="1e-6" iyz="0.0"
        izz="1e-6"
      />
    </inertial>

    <collision>
      <origin xyz="0 0 0" rpy="0 0 0"/>
      <geometry>
        <box size="0.1 0.1 0.1"/>
      </geometry>
    </collision>

    <visual>
      <origin xyz="0 0 0" rpy="0 0 0"/>
      <geometry>
        <mesh filename="package://trixy/meshes/hokuyo.dae"/>
      </geometry>
    </visual>

  </link>

  <link name="left_wheel">
    <inertial>
      <mass value="5"/>
      <origin xyz="0 0 0" rpy="0 1.5707 1.5707"/>
      <inertia
        ixx="0.1" ixy="0.0" ixz="0.0"
        iyy="0.1" iyz="0.0"
        izz="0.1"
      />
    </inertial>

    <collision>
      <origin xyz="0 0 0" rpy="0 1.5707 1.5707"/>
      <geometry>
        <cylinder radius="0.08" length="0.04"/>
      </geometry>
    </collision>

    <visual>
      <origin xyz="0 0 0" rpy="0 1.5707 1.5707"/>
      <geometry>
        <cylinder radius="0.08" length="0.04"/>
      </geometry>
    </visual>

  </link>

  <link name="right_wheel">
    <inertial>
      <mass value="5"/>
      <origin xyz="0 0 0" rpy="0 1.5707 1.5707"/>
      <inertia
        ixx="0.1" ixy="0.0" ixz="0.0"
        iyy="0.1" iyz="0.0"
        izz="0.1"
      />
    </inertial>

    <collision>
      <origin xyz="0 0 0" rpy="0 1.5707 1.5707"/>
      <geometry>
        <cylinder radius="0.08" length="0.04"/>
      </geometry>
    </collision>

    <visual>
      <origin xyz="0 0 0" rpy="0 1.5707 1.5707"/>
      <geometry>
        <cylinder radius="0.08" length="0.04"/>
      </geometry>
    </visual>

  </link>

  <link name='chassis'>
    <pose>0 0 0.1 0 0 0</pose>

    <inertial>
      <mass value="25.0"/>
      <origin xyz="0.0 0 0" rpy=" 0 0 0"/>
      <inertia
          ixx="0.1" ixy="0" ixz="0"
          iyy="0.1" iyz="0"
          izz="0.1"
      />
    </inertial>

    <collision name='chassis_collision'>
      <origin xyz="0 0 0.05" rpy=" 0 0 0"/>
      <geometry>
        <box size="0.3 0.3 0.1"/>
      </geometry>
    </collision>

    <visual name='chassis_visual'>
      <origin xyz="0 0 0.05" rpy=" 0 0 0"/>
      <geometry>
        <box size="0.3 0.3 0.1"/>
      </geometry>
    </visual>

    <collision name='back_caster_collision'>
      <origin xyz="-0.11 0 -0.03" rpy=" 0 0 0"/>
      <geometry>
        <sphere radius="0.0499"/>
      </geometry>
    </collision>

    <visual name='back_caster_visual'>
      <origin xyz="-0.11 0 -0.03" rpy=" 0 0 0"/>
      <geometry>
        <sphere radius="0.05"/>
      </geometry>
    </visual>

    <collision name='front_caster_collision'>
      <origin xyz="0.11 0 -0.03" rpy=" 0 0 0"/>
      <geometry>
        <sphere radius="0.0499"/>
      </geometry>
    </collision>

    <visual name='front_caster_visual'>
      <origin xyz="0.11 0 -0.03" rpy=" 0 0 0"/>
      <geometry>
        <sphere radius="0.05"/>
      </geometry>
    </visual>

  </link>

</robot>